{
  "action": {
    "error": {
      "variety": [
        "Programming error"
      ],
      "vector": [
        "Unknown"
      ]
    }
  },
  "actor": {
    "internal": {
      "motive": [
        "NA"
      ],
      "variety": [
        "Unknown",
        "Developer"
      ]
    }
  },
  "asset": {
    "assets": [
      {
        "variety": "S - Unknown"
      }
    ]
  },
  "attribute": {
    "confidentiality": {
      "data": [
        {
          "amount": 1,
          "variety": "Personal"
        }
      ],
      "data_disclosure": "Yes",
      "data_total": 1,
      "data_victim": [
        "Employee"
      ],
      "state": [
        "Unknown"
      ]
    }
  },
  "discovery_method": "Int - reported by employee",
  "impact": {
    "overall_rating": "Unknown"
  },
  "incident_id": "F155F2D7-F75F-4FB2-967D-C2235659110D",
  "plus": {
  "IOI_Impact_Score": 2,
  "IOI_media_coverage": "Yes",
  "IOI_under_1k_records": "Yes",
    "analysis_status": "Finalized",
    "analyst": "Robert-Topper",
    "attribute": {
      "confidentiality": {
        "credit_monitoring": "Y",
        "data_misuse": "Y"
      }
    },
    "created": "2016-10-07T12:35:00Z",
    "dbir_year": 2017,
    "github": "7082",
    "master_id": "A250C158-A023-4A66-BE80-A0AA58F426CA",
    "modified": "2016-11-04T19:04:00Z",
    "sub_source": "VCDB",
    "timeline": {
      "notification": {
        "day": 24,
        "month": 1,
        "year": 2016
      }
    }
  },
  "reference": "http://www.theverge.com/2016/1/25/10827996/uber-driver-personal-data-mistake-glitch",
  "schema_version": "1.3.2",
  "security_incident": "Confirmed",
  "source_id": "vcdb",
  "summary": "PII mistakenly sent to other drivers as the result of a software glitch",
  "timeline": {
    "incident": {
      "day": 24,
      "month": 1,
      "year": 2016
    }
  },
  "victim": {
    "country": [
      "US"
    ],
    "employee_count": "1001 to 10000",
    "industry": "485310",
    "region": [
      "019021"
    ],
    "state": "CA",
    "victim_id": "Uber"
  }
}
